nohup: ignoring input
Traceback (most recent call last):
  File "train_model.py", line 127, in <module>
    train_model()
  File "train_model.py", line 91, in train_model
    enhanced = generator(raw_image.detach())
  File "/root/anaconda3/lib/python3.8/site-packages/torch/nn/modules/module.py", line 727, in _call_impl
    result = self.forward(*input, **kwargs)
  File "/root/anaconda3/lib/python3.8/site-packages/torch/nn/parallel/data_parallel.py", line 161, in forward
    outputs = self.parallel_apply(replicas, inputs, kwargs)
  File "/root/anaconda3/lib/python3.8/site-packages/torch/nn/parallel/data_parallel.py", line 171, in parallel_apply
    return parallel_apply(replicas, inputs, kwargs, self.device_ids[:len(replicas)])
  File "/root/anaconda3/lib/python3.8/site-packages/torch/nn/parallel/parallel_apply.py", line 86, in parallel_apply
    output.reraise()
  File "/root/anaconda3/lib/python3.8/site-packages/torch/_utils.py", line 428, in reraise
    raise self.exc_type(msg)
RuntimeError: Caught RuntimeError in replica 0 on device 0.
Original Traceback (most recent call last):
  File "/root/anaconda3/lib/python3.8/site-packages/torch/nn/parallel/parallel_apply.py", line 61, in _worker
    output = module(*input, **kwargs)
  File "/root/anaconda3/lib/python3.8/site-packages/torch/nn/modules/module.py", line 727, in _call_impl
    result = self.forward(*input, **kwargs)
  File "/ljj1016/attack-ISP/proxy_model/network.py", line 238, in forward
    x = self.Decoder1(x)
  File "/root/anaconda3/lib/python3.8/site-packages/torch/nn/modules/module.py", line 727, in _call_impl
    result = self.forward(*input, **kwargs)
  File "/root/anaconda3/lib/python3.8/site-packages/torch/nn/modules/container.py", line 117, in forward
    input = module(input)
  File "/root/anaconda3/lib/python3.8/site-packages/torch/nn/modules/module.py", line 727, in _call_impl
    result = self.forward(*input, **kwargs)
  File "/root/anaconda3/lib/python3.8/site-packages/torch/nn/modules/conv.py", line 423, in forward
    return self._conv_forward(input, self.weight)
  File "/root/anaconda3/lib/python3.8/site-packages/torch/nn/modules/conv.py", line 419, in _conv_forward
    return F.conv2d(input, weight, self.bias, self.stride,
RuntimeError: CUDA out of memory. Tried to allocate 61.30 GiB (GPU 0; 31.75 GiB total capacity; 24.78 GiB already allocated; 5.61 GiB free; 25.02 GiB reserved in total by PyTorch)

